Workbook

Sheet Introduction
A1: Discounted Cash Flow Valuation Study
A3: Professional portfolio case study | Publicly traded company | Integrated operating forecast, WACC and valuation sensitivity
A5: PROFESSIONAL PROFILE | F5: PROJECT PURPOSE
A6: Name | C6: Walid Takhim | F6: This workbook demonstrates the ability to build a complete, auditable DCF model for a publicly traded company—from historical financial analysis and operating forecasts to free cash flow valuation and scenario testing.
A7: Role | C7: Financial Analyst
A8: Focus | C8: Corporate valuation & financial modeling
A10: MODEL CAPABILITIES DEMONSTRATED
A11: OPERATING FORECAST | D11: FREE CASH FLOW | G11: COST OF CAPITAL | J11: VALUATION
A12: Revenue growth, cost structure, EBITDA, taxes and margin development based on historical performance and explicit assumptions. | D12: Unlevered free cash flow derived from NOPAT, D&A, capital expenditure and changes in net working capital. | G12: WACC built from capital structure, cost of debt, tax rate, risk-free rate, market risk premium and levered beta. | J12: Enterprise and equity value, implied share price, terminal value and two-variable sensitivity analysis.
A16: ANALYTICAL WORKFLOW
A17: 01 ANALYZE | D17: 02 FORECAST | G17: 03 VALUE | J17: 04 TEST
A18: Normalize historical income statement, balance sheet and cash flow data; identify operating drivers and working-capital trends. | D18: Translate business drivers into revenue, margins, fixed assets, working capital and unlevered free cash flow projections. | G18: Discount forecast cash flows, estimate terminal value, bridge enterprise value to equity value and calculate implied value per share. | J18: Assess valuation sensitivity to WACC and perpetual growth assumptions and highlight model risks and key dependencies.
A22: KEY DELIVERABLES
A23: • Integrated historical and forecast financial statements • Revenue, margin, CapEx and working-capital assumptions • Unlevered free cash flow schedule • WACC and terminal-value calculation • Implied enterprise value, equity value and share price • WACC / perpetual-growth sensitivity matrix | G23: WORKBOOK STRUCTURE Free Cash Flow | Fixed Assets | Net Working Capital DCF | WACC | Income Statement Balance Sheet | Cash Flow Statement | Analysis & Insights
A28: Portfolio note — This model is presented as evidence of financial-modeling capability. Assumptions are illustrative and should be refreshed with current company, industry and macroeconomic data before any investment use.
A31: MODEL CONVENTION • Blue = hard-coded input • Green = cross-sheet link • Black = calculation

Sheet Analysis & Insights
A1: DCF Analysis — Trends and Key Insights
A2: Historical 2019–2021 and forecast 2022–2026 | Amounts in millions, except per-share value
A4: 2026E REVENUE | D4: 2021A–2026E REVENUE CAGR | G4: 2026E UFCF | J4: IMPLIED SHARE PRICE
A5: ='Free Cash Flow'!J4 -> 290324.49 | D5: =('Free Cash Flow'!J4/'Free Cash Flow'!E4)^(1/5)-1 -> 0.081824939 | G5: ='Free Cash Flow'!J21 -> 4963.3221 | J5: =DCF!C21 -> 242.72775
A7: +48.2% vs 2021A | D7: Decelerating growth | G7: +5.6% vs 2021A | J7: Base-case valuation
A9: KEY INSIGHTS | I9: MODEL REVIEW POINT
A10: 1 | B10: Revenue increases 48.2% between 2021A and 2026E, but annual growth slows from 17.5% to 5.0%. | I10: Projected working capital not reflected in UFCF
A11: 2 | B11: EBITDA increases 44.3%, slightly below revenue growth; the EBITDA margin declines from 4.33% to 4.22%. | I11: The detailed schedule projects increasingly negative net working capital, while the “Change in NWC” line in Free Cash Flow is blank for 2022E–2026E. The diagnostic below isolates the potential impact without changing the DCF.
A12: 3 | B12: UFCF grows only 5.6% over the same period and falls sharply in 2022E before recovering.
A13: 4 | B13: The present value of the terminal value represents 82.5% of enterprise value, making valuation highly sensitive to WACC and perpetual growth.
A15: ="Working-capital diagnostic: 2026E UFCF would increase from "&ROUND(E58,0)&" to "&ROUND(I58,0)&" if the detailed NWC change were included (illustrative analysis)." -> Working-capital diagnostic: 2026E UFCF would increase from 4963 to 5700 if the detailed NWC change were included (illustrative analysis).
A49: CHART DATA — formulas linked to the financial model
A50: Fiscal Year | B50: Revenue | C50: EBITDA | D50: EBITDA Margin | E50: Reported UFCF | F50: Revenue Growth | G50: Detailed NWC | H50: Change in Detailed NWC | I50: UFCF incl. NWC Change | J50: Revenue Index | K50: EBITDA Index | M50: Enterprise Value Component | N50: Value
A51: 2019A | B51: ='Free Cash Flow'!C4 -> 152703 | C51: ='Free Cash Flow'!C10 -> 6229 | D51: =C51/B51 -> 0.040791602 | E51: ='Free Cash Flow'!C21 -> 3158 | G51: ='Net Working Capital'!D7-'Net Working Capital'!D14 -> -7497 | H51: =G51-('Net Working Capital'!C7-'Net Working Capital'!C14) -> -691 | I51: =E51 -> 3158 | J51: =B51/$B$51*100 -> 100 | K51: =C51/$C$51*100 -> 100 | M51: PV of Explicit FCF | N51: =DCF!C10 -> 18301.802
A52: 2020A | B52: ='Free Cash Flow'!D4 -> 166761 | C52: ='Free Cash Flow'!D10 -> 7080 | D52: =C52/B52 -> 0.04245597 | E52: ='Free Cash Flow'!D21 -> 2859 | F52: ='Free Cash Flow'!D25 -> 0.09206106 | G52: ='Net Working Capital'!E7-'Net Working Capital'!E14 -> -9934 | H52: =G52-('Net Working Capital'!D7-'Net Working Capital'!D14) -> -2437 | I52: =E52 -> 2859 | J52: =B52/$B$51*100 -> 109.20611 | K52: =C52/$C$51*100 -> 113.6619 | M52: PV of Terminal Value | N52: =DCF!C14 -> 86300.303
A53: 2021A | B53: ='Free Cash Flow'!E4 -> 195929 | C53: ='Free Cash Flow'!E10 -> 8489 | D53: =C53/B53 -> 0.043326919 | E53: ='Free Cash Flow'!E21 -> 4698 | F53: ='Free Cash Flow'!E25 -> 0.174909 | G53: ='Net Working Capital'!F7-'Net Working Capital'!F14 -> -11312 | H53: =G53-('Net Working Capital'!E7-'Net Working Capital'!E14) -> -1378 | I53: =E53 -> 4698 | J53: =B53/$B$51*100 -> 128.30724 | K53: =C53/$C$51*100 -> 136.28191
A54: 2022E | B54: ='Free Cash Flow'!F4 -> 215521.9 | C54: ='Free Cash Flow'!F10 -> 9093.1916 | D54: =C54/B54 -> 0.042191497 | E54: ='Free Cash Flow'!F21 -> 3645.4724 | F54: ='Free Cash Flow'!F25 -> 0.1 | G54: ='Net Working Capital'!G7-'Net Working Capital'!G14 -> -11538.895 | H54: =G54-('Net Working Capital'!F7-'Net Working Capital'!F14) -> -226.89531 | I54: =E54-H54 -> 3872.3677 | J54: =B54/$B$51*100 -> 141.13796 | K54: =C54/$C$51*100 -> 145.98156
A55: 2023E | B55: ='Free Cash Flow'!G4 -> 237074.09 | C55: ='Free Cash Flow'!G10 -> 10002.511 | D55: =C55/B55 -> 0.042191497 | E55: ='Free Cash Flow'!G21 -> 4100.7944 | F55: ='Free Cash Flow'!G25 -> 0.1 | G55: ='Net Working Capital'!H7-'Net Working Capital'!H14 -> -12632.394 | H55: =G55-('Net Working Capital'!G7-'Net Working Capital'!G14) -> -1093.499 | I55: =E55-H55 -> 5194.2934 | J55: =B55/$B$51*100 -> 155.25176 | K55: =C55/$C$51*100 -> 160.57972
A56: 2024E | B56: ='Free Cash Flow'!H4 -> 258410.76 | C56: ='Free Cash Flow'!H10 -> 10902.737 | D56: =C56/B56 -> 0.042191497 | E56: ='Free Cash Flow'!H21 -> 4529.3774 | F56: ='Free Cash Flow'!H25 -> 0.09 | G56: ='Net Working Capital'!I7-'Net Working Capital'!I14 -> -13769.31 | H56: =G56-('Net Working Capital'!H7-'Net Working Capital'!H14) -> -1136.9155 | I56: =E56-H56 -> 5666.2929 | J56: =B56/$B$51*100 -> 169.22441 | K56: =C56/$C$51*100 -> 175.0319
A57: 2025E | B57: ='Free Cash Flow'!I4 -> 276499.51 | C57: ='Free Cash Flow'!I10 -> 11665.928 | D57: =C57/B57 -> 0.042191497 | E57: ='Free Cash Flow'!I21 -> 4828.694 | F57: ='Free Cash Flow'!I25 -> 0.07 | G57: ='Net Working Capital'!J7-'Net Working Capital'!J14 -> -14733.161 | H57: =G57-('Net Working Capital'!I7-'Net Working Capital'!I14) -> -963.85169 | I57: =E57-H57 -> 5792.5457 | J57: =B57/$B$51*100 -> 181.07012 | K57: =C57/$C$51*100 -> 187.28413
A58: 2026E | B58: ='Free Cash Flow'!J4 -> 290324.49 | C58: ='Free Cash Flow'!J10 -> 12249.225 | D58: =C58/B58 -> 0.042191497 | E58: ='Free Cash Flow'!J21 -> 4963.3221 | F58: ='Free Cash Flow'!J25 -> 0.05 | G58: ='Net Working Capital'!K7-'Net Working Capital'!K14 -> -15469.82 | H58: =G58-('Net Working Capital'!J7-'Net Working Capital'!J14) -> -736.65807 | I58: =E58-H58 -> 5699.9802 | J58: =B58/$B$51*100 -> 190.12363 | K58: =C58/$C$51*100 -> 196.64833

Sheet Free Cash Flow
B2: Unlevered Free Cash Flow (mm)
B3: Fiscal Year | C3: 43830 | D3: 44196 | E3: 44561 | F3: 44926 | G3: 45291 | H3: 45657 | I3: 46022 | J3: 46387
B4: Revenue | C4: ='Income Statement'!C5 -> 152703 | D4: ='Income Statement'!D5 -> 166761 | E4: ='Income Statement'!E5 -> 195929 | F4: =E4*(1+F25) -> 215521.9 | G4: =F4*(1+G25) -> 237074.09 | H4: =G4*(1+H25) -> 258410.76 | I4: =H4*(1+I25) -> 276499.51 | J4: =I4*(1+J25) -> 290324.49
B5: COGS | C5: ='Income Statement'!C7 -> 132886 | D5: ='Income Statement'!D7 -> 144939 | E5: ='Income Statement'!E7 -> 170684 | F5: =F4*F27 -> 187541.38 | G5: =G4*G27 -> 206295.52 | H5: =H4*H27 -> 224862.11 | I5: =I4*I27 -> 240602.46 | J5: =J4*J27 -> 252632.59
B6: Gross Profit | C6: =C4-C5 -> 19817 | D6: =D4-D5 -> 21822 | E6: =E4-E5 -> 25245 | F6: =F4-F5 -> 27980.52 | G6: =G4-G5 -> 30778.572 | H6: =H4-H5 -> 33548.644 | I6: =I4-I5 -> 35897.049 | J6: =J4-J5 -> 37691.901
B7: Operating Expenses
B8: Selling, General, Administrative | C8: =SUM('Income Statement'!C8,'Income Statement'!C10) -> 13588 | D8: =SUM('Income Statement'!D8,'Income Statement'!D10) -> 14742 | E8: =SUM('Income Statement'!E8,'Income Statement'!E10) -> 16756 | F8: =F9 -> 18887.328 | G8: =G9 -> 20776.061 | H8: =H9 -> 22645.907 | I8: =I9 -> 24231.12 | J8: =J9 -> 25442.676
B9: Total Operating Expenses | C9: =SUM(C8) -> 13588 | D9: =SUM(D8) -> 14742 | E9: =SUM(E8) -> 16756 | F9: =F4*F28 -> 18887.328 | G9: =G4*G28 -> 20776.061 | H9: =H4*H28 -> 22645.907 | I9: =I4*I28 -> 24231.12 | J9: =J4*J28 -> 25442.676
B10: EBITDA | C10: =C6-C9 -> 6229 | D10: =D6-D9 -> 7080 | E10: =E6-E9 -> 8489 | F10: =F6-F9 -> 9093.1916 | G10: =G6-G9 -> 10002.511 | H10: =H6-H9 -> 10902.737 | I10: =I6-I9 -> 11665.928 | J10: =J6-J9 -> 12249.225
B11: Depreciation & Amortization | C11: ='Income Statement'!C9 -> 1492 | D11: ='Income Statement'!D9 -> 1645 | E11: ='Income Statement'!E9 -> 1781 | F11: ='Fixed Assets'!F5 -> 1995.9571 | G11: ='Fixed Assets'!G5 -> 2144.3445 | H11: ='Fixed Assets'!H5 -> 2303.7636 | I11: ='Fixed Assets'!I5 -> 2475.0346 | J11: ='Fixed Assets'!J5 -> 2659.0385
B12: Operating Profit (EBIT) | C12: =C10-C11 -> 4737 | D12: =D10-D11 -> 5435 | E12: =E10-E11 -> 6708 | F12: =F10-F11 -> 7097.2345 | G12: =G10-G11 -> 7858.1663 | H12: =H10-H11 -> 8598.9731 | I12: =I10-I11 -> 9190.8938 | J12: =J10-J11 -> 9590.1863
B13: Operating Taxes | C13: ='Income Statement'!C16 -> 1061 | D13: ='Income Statement'!D16 -> 1308 | E13: ='Income Statement'!E16 -> 1601 | F13: =F12*F29 -> 1490.4192 | G13: =G12*G29 -> 1650.2149 | H13: =H12*H29 -> 1805.7844 | I13: =I12*I29 -> 1930.0877 | J13: =J12*J29 -> 2013.9391
B14: NOPAT (Net Operating Profit After Taxes) | C14: =C12-C13 -> 3676 | D14: =D12-D13 -> 4127 | E14: =E12-E13 -> 5107 | F14: =F12-F13 -> 5606.8153 | G14: =G12-G13 -> 6207.9514 | H14: =H12-H13 -> 6793.1888 | I14: =I12-I13 -> 7260.8061 | J14: =J12-J13 -> 7576.2471
B15: (+) Depreciation & Amortization | C15: =C11 -> 1492 | D15: =D11 -> 1645 | E15: =E11 -> 1781 | F15: =F11 -> 1995.9571 | G15: =G11 -> 2144.3445 | H15: =H11 -> 2303.7636 | I15: =I11 -> 2475.0346 | J15: =J11 -> 2659.0385
B16: (-) Capital Expenditures | C16: ='Fixed Assets'!C6 -> 2701 | D16: ='Fixed Assets'!D6 -> 5350 | E16: ='Fixed Assets'!E6 -> 3568 | F16: ='Fixed Assets'!F6 -> 3957.3 | G16: ='Fixed Assets'!G6 -> 4251.5014 | H16: ='Fixed Assets'!H6 -> 4567.575 | I16: ='Fixed Assets'!I6 -> 4907.1467 | J16: ='Fixed Assets'!J6 -> 5271.9635
B17: (-) Change in NWC | C17: =C18-('Net Working Capital'!C7-'Net Working Capital'!C14) -> -691 | D17: =D18-C18 -> -2437 | E17: =E18-D18 -> -1378
B18: NWC | C18: =C19-C20 -> -7497 | D18: =D19-D20 -> -9934 | E18: =E19-E20 -> -11312 | F18: =F19-F20 -> -11312 | G18: =G19-G20 -> -11312 | H18: =H19-H20 -> -11312 | I18: =I19-I20 -> -11312 | J18: =J19-J20 -> -11312
B19: Current Assets | C19: ='Net Working Capital'!D7 -> 14041 | D19: ='Net Working Capital'!E7 -> 14815 | E19: ='Net Working Capital'!F7 -> 17330 | F19: =SUM(F16:F18) -> 3957.3 | G19: =SUM(G16:G18) -> 4251.5014 | H19: =SUM(H16:H18) -> 4567.575 | I19: =SUM(I16:I18) -> 4907.1467 | J19: =SUM(J16:J18) -> 5271.9635
B20: Current Liabilities | C20: ='Net Working Capital'!D14 -> 21538 | D20: ='Net Working Capital'!E14 -> 24749 | E20: ='Net Working Capital'!F14 -> 28642 | F20: =SUM(F15:F19) -> 9910.5571 | G20: =SUM(G15:G19) -> 10647.347 | H20: =SUM(H15:H19) -> 11438.914 | I20: =SUM(I15:I19) -> 12289.328 | J20: =SUM(J15:J19) -> 13202.965
B21: Unlevered Free Cash Flow | C21: =C14+C15-C16-C17 -> 3158 | D21: =D14+D15-D16-D17 -> 2859 | E21: =E14+E15-E16-E17 -> 4698 | F21: =F14+F15-F16-F17 -> 3645.4724 | G21: =G14+G15-G16-G17 -> 4100.7944 | H21: =H14+H15-H16-H17 -> 4529.3774 | I21: =I14+I15-I16-I17 -> 4828.694 | J21: =J14+J15-J16-J17 -> 4963.3221
B23: Assumptions
B24: =B3 -> Fiscal Year | C24: =C3 -> 43830 | D24: =D3 -> 44196 | E24: =E3 -> 44561 | F24: =F3 -> 44926 | G24: =G3 -> 45291 | H24: =H3 -> 45657 | I24: =I3 -> 46022 | J24: =J3 -> 46387
B25: Revenue Growth | D25: =D4/C4-1 -> 0.09206106 | E25: =E4/D4-1 -> 0.174909 | F25: 0.1 | G25: 0.1 | H25: 0.09 | I25: 0.07 | J25: 0.05
B27: COGS % of Revenue | C27: =C5/C4 -> 0.87022521 | D27: =D5/D4 -> 0.86914207 | E27: =E5/E4 -> 0.87115231 | F27: =AVERAGE(C27:E27) -> 0.87017319 | G27: =F27 -> 0.87017319 | H27: =G27 -> 0.87017319 | I27: =H27 -> 0.87017319 | J27: =I27 -> 0.87017319
B28: SG&A % of Revenue | C28: =C8/C4 -> 0.08898319 | D28: =D8/D4 -> 0.088401964 | E28: =E8/E4 -> 0.085520775 | F28: =AVERAGE(C28:E28) -> 0.08763531 | G28: =F28 -> 0.08763531 | H28: =G28 -> 0.08763531 | I28: =H28 -> 0.08763531 | J28: =I28 -> 0.08763531
B29: Tax % of EBIT | C29: =C13/C12 -> 0.22398142 | D29: =D13/D12 -> 0.24066237 | E29: =E13/E12 -> 0.23867024 | F29: 0.21 | G29: 0.21 | H29: 0.21 | I29: 0.21 | J29: 0.21

Sheet Fixed Assets
B2: Fixed Assets Schedule
B3: Fiscal Year | C3: 43830 | D3: 44196 | E3: 44561 | F3: 44926 | G3: 45291 | H3: 45657 | I3: 46022 | J3: 46387
B4: Beginning PP&E | C4: =SUM('Balance Sheet'!C11:C12) -> 19681 | D4: =SUM('Balance Sheet'!D11:D12) -> 20890 | E4: =SUM('Balance Sheet'!E11:E12) -> 24595 | F4: =E7 -> 26382 | G4: =F7 -> 28343.343 | H4: =G7 -> 30450.5 | I4: =H7 -> 32714.311 | J4: =I7 -> 35146.423
B5: D&A | C5: ='Free Cash Flow'!C11 -> 1492 | D5: ='Free Cash Flow'!D11 -> 1645 | E5: ='Free Cash Flow'!E11 -> 1781 | F5: =F4*F11 -> 1995.9571 | G5: =G4*G11 -> 2144.3445 | H5: =H4*H11 -> 2303.7636 | I5: =I4*I11 -> 2475.0346 | J5: =J4*J11 -> 2659.0385
B6: CapEx | C6: =C7-C4+C5 -> 2701 | D6: =D7-D4+D5 -> 5350 | E6: =E7-E4+E5 -> 3568 | F6: =F4*F12 -> 3957.3 | G6: =G4*G12 -> 4251.5014 | H6: =H4*H12 -> 4567.575 | I6: =I4*I12 -> 4907.1467 | J6: =J4*J12 -> 5271.9635
B7: Ending PP&E | C7: =SUM('Balance Sheet'!D11:D12) -> 20890 | D7: =SUM('Balance Sheet'!E11:E12) -> 24595 | E7: =SUM('Balance Sheet'!F11:F12) -> 26382 | F7: =F4-F5+F6 -> 28343.343 | G7: =G4-G5+G6 -> 30450.5 | H7: =H4-H5+H6 -> 32714.311 | I7: =I4-I5+I6 -> 35146.423 | J7: =J4-J5+J6 -> 37759.348
B9: Assumptions
B10: Fiscal Year | C10: 43830 | D10: 44196 | E10: 44561 | F10: 44926 | G10: 45291 | H10: 45657 | I10: 46022 | J10: 46387
B11: D&A as a % of Beginning PP&E | C11: =C5/C4 -> 0.075809156 | D11: =D5/D4 -> 0.078745811 | E11: =E5/E4 -> 0.072413092 | F11: =AVERAGE(C11:E11) -> 0.07565602 | G11: =F11 -> 0.07565602 | H11: =G11 -> 0.07565602 | I11: =H11 -> 0.07565602 | J11: =I11 -> 0.07565602
B12: CapEx as a % of Beginning PP&E | C12: =C6/C4 -> 0.13723896 | D12: =D6/D4 -> 0.2561034 | E12: =E6/E4 -> 0.14507014 | F12: 0.15 | G12: =F12 -> 0.15 | H12: =G12 -> 0.15 | I12: =H12 -> 0.15 | J12: =I12 -> 0.15

Sheet Net Working Capital
B2: Net Working Capital
B3: Fiscal Year | C3: 43465 | D3: 43830 | E3: 44196 | F3: 44561 | G3: 44926 | H3: 45291 | I3: 45657 | J3: 46022 | K3: 46387
B4: Accounts Receivables | C4: ='Balance Sheet'!C6 -> 1669 | D4: ='Balance Sheet'!D6 -> 1535 | E4: ='Balance Sheet'!E6 -> 1550 | F4: ='Balance Sheet'!F6 -> 1803 | G4: =G21*G18/360 -> 2155.219 | H4: =H21*H18/360 -> 2370.7409 | I4: =I21*I18/360 -> 2584.1076 | J4: =J21*J18/360 -> 2764.9951 | K4: =K21*K18/360 -> 2903.2449
B5: Merchandise Inventory | C5: ='Balance Sheet'!C7 -> 11040 | D5: ='Balance Sheet'!D7 -> 11395 | E5: ='Balance Sheet'!E7 -> 12242 | F5: ='Balance Sheet'!F7 -> 14215 | G5: =G22*G19/360 -> 16097.302 | H5: =H22*H19/360 -> 17707.032 | I5: =I22*I19/360 -> 19300.665 | J5: =J22*J19/360 -> 20651.711 | K5: =K22*K19/360 -> 21684.297
B6: Other Current Assets | C6: ='Balance Sheet'!C8 -> 321 | D6: ='Balance Sheet'!D8 -> 1111 | E6: ='Balance Sheet'!E8 -> 1023 | F6: ='Balance Sheet'!F8 -> 1312 | G6: =G25*G$18 -> 1205.507 | H6: =H25*H$18 -> 1422.4445 | I6: =I25*I$18 -> 1550.4645 | J6: =J25*J$18 -> 1658.9971 | K6: =K25*K$18 -> 1741.9469
B7: Current Assets | C7: =SUM(C4:C6) -> 13030 | D7: =SUM(D4:D6) -> 14041 | E7: =SUM(E4:E6) -> 14815 | F7: =SUM(F4:F6) -> 17330 | G7: =SUM(G4:G6) -> 19458.028 | H7: =SUM(H4:H6) -> 21500.217 | I7: =SUM(I4:I6) -> 23435.237 | J7: =SUM(J4:J6) -> 25075.704 | K7: =SUM(K4:K6) -> 26329.489
B8: Current Liabilities
B9: Accounts Payable | C9: ='Balance Sheet'!C16 -> 11237 | D9: ='Balance Sheet'!D16 -> 11679 | E9: ='Balance Sheet'!E16 -> 14172 | F9: ='Balance Sheet'!F16 -> 16278 | G9: =G23*G19/360 -> 17451.767 | H9: =H23*H19/360 -> 19196.944 | I9: =I23*I19/360 -> 20924.669 | J9: =J23*J19/360 -> 22389.396 | K9: =K23*K19/360 -> 23508.866
B10: Accrued Salaries and Benefits | C10: ='Balance Sheet'!C17 -> 2994 | D10: ='Balance Sheet'!D17 -> 3176 | E10: ='Balance Sheet'!E17 -> 3605 | F10: ='Balance Sheet'!F17 -> 4090 | G10: =G26*G$18 -> 4525.9599 | H10: =H26*H$18 -> 4978.5559 | I10: =I26*I$18 -> 5426.6259 | J10: =J26*J$18 -> 5806.4897 | K10: =K26*K$18 -> 6096.8142
B11: Accrued Member Rewards | C11: ='Balance Sheet'!C18 -> 1057 | D11: ='Balance Sheet'!D18 -> 1180 | E11: ='Balance Sheet'!E18 -> 1393 | F11: ='Balance Sheet'!F18 -> 1671 | G11: =G27*G$18 -> 1728.2294 | H11: =H27*H$18 -> 1896.5927 | I11: =I27*I$18 -> 2067.2861 | J11: =J27*J$18 -> 2211.9961 | K11: =K27*K$18 -> 2322.5959
B12: Deferred Membership Fees | C12: ='Balance Sheet'!C19 -> 1624 | D12: ='Balance Sheet'!D19 -> 1711 | E12: ='Balance Sheet'!E19 -> 1851 | F12: ='Balance Sheet'!F19 -> 2042 | G12: =G28*G$18 -> 2381.3816 | H12: =H28*H$18 -> 2607.815 | I12: =I28*I$18 -> 2842.5183 | J12: =J28*J$18 -> 3041.4946 | K12: =K28*K$18 -> 3193.5694
B13: Other Current Liabilities | C13: ='Balance Sheet'!C21 -> 2924 | D13: ='Balance Sheet'!D21 -> 3792 | E13: ='Balance Sheet'!E21 -> 3728 | F13: ='Balance Sheet'!F21 -> 4561 | G13: =G29*G$18 -> 4909.5848 | H13: =H29*H$18 -> 5452.7041 | I13: =I29*I$18 -> 5943.4474 | J13: =J29*J$18 -> 6359.4888 | K13: =K29*K$18 -> 6677.4632
B14: Current Liabilities | C14: =SUM(C9:C13) -> 19836 | D14: =SUM(D9:D13) -> 21538 | E14: =SUM(E9:E13) -> 24749 | F14: =SUM(F9:F13) -> 28642 | G14: =SUM(G9:G13) -> 30996.923 | H14: =SUM(H9:H13) -> 34132.612 | I14: =SUM(I9:I13) -> 37204.547 | J14: =SUM(J9:J13) -> 39808.865 | K14: =SUM(K9:K13) -> 41799.308
B16: Assumptions
B17: Fiscal Year | C17: 43465 | D17: 43830 | E17: 44196 | F17: 44561 | G17: 44926 | H17: 45291 | I17: 45657 | J17: 46022 | K17: 46387
B18: Revenue | C18: 141576 | D18: ='Free Cash Flow'!C4 -> 152703 | E18: ='Free Cash Flow'!D4 -> 166761 | F18: ='Free Cash Flow'!E4 -> 195929 | G18: ='Free Cash Flow'!F4 -> 215521.9 | H18: ='Free Cash Flow'!G4 -> 237074.09 | I18: ='Free Cash Flow'!H4 -> 258410.76 | J18: ='Free Cash Flow'!I4 -> 276499.51 | K18: ='Free Cash Flow'!J4 -> 290324.49
B19: COGS | C19: 123152 | D19: ='Free Cash Flow'!C5 -> 132886 | E19: ='Free Cash Flow'!D5 -> 144939 | F19: ='Free Cash Flow'!E5 -> 170684 | G19: ='Free Cash Flow'!F5 -> 187541.38 | H19: ='Free Cash Flow'!G5 -> 206295.52 | I19: ='Free Cash Flow'!H5 -> 224862.11 | J19: ='Free Cash Flow'!I5 -> 240602.46 | K19: ='Free Cash Flow'!J5 -> 252632.59
B21: Days Sales Outstanding (DSO) | C21: =C4/C18*360 -> 4.2439397 | D21: =D4/D18*360 -> 3.6187894 | E21: =E4/E18*360 -> 3.3461061 | F21: =F4/F18*360 -> 3.3128327 | G21: =3.6 -> 3.6 | H21: =3.6 -> 3.6 | I21: =3.6 -> 3.6 | J21: =3.6 -> 3.6 | K21: =3.6 -> 3.6
B22: Days Inventory Outstanding (DIO) | C22: =C5/C19*360 -> 32.272314 | D22: =D5/D19*360 -> 30.870069 | E22: =E5/E19*360 -> 30.406723 | F22: =F5/F19*360 -> 29.981721 | G22: 30.9 | H22: 30.9 | I22: 30.9 | J22: 30.9 | K22: 30.9
B23: Days Payable Outstanding (DPO) | C23: =C9/C19*360 -> 32.848188 | D23: =D9/D19*360 -> 31.63945 | E23: =E9/E19*360 -> 35.200464 | F23: =F9/F19*360 -> 34.332919 | G23: 33.5 | H23: 33.5 | I23: 33.5 | J23: 33.5 | K23: 33.5
B25: Other Current Assets as a % of Revenue | C25: =C6/C18 -> 0.0022673334 | D25: =D6/D18 -> 0.0072755611 | E25: =E6/E18 -> 0.0061345279 | F25: =F6/F18 -> 0.0066963033 | G25: =AVERAGE(C25:F25) -> 0.0055934314 | H25: =0.6% -> 0.006 | I25: =0.6% -> 0.006 | J25: =0.6% -> 0.006 | K25: =0.6% -> 0.006
B26: Accrued Salaries as a % of Revenue | C26: =C10/C18 -> 0.021147652 | D26: =D10/D18 -> 0.020798544 | E26: =E10/E18 -> 0.021617764 | F26: =F10/F18 -> 0.020874909 | G26: 0.021 | H26: 0.021 | I26: 0.021 | J26: 0.021 | K26: 0.021
B27: Accrued Member Rewards as a % of Revenue | C27: =C11/C18 -> 0.0074659547 | D27: =D11/D18 -> 0.0077274186 | E27: =E11/E18 -> 0.008353272 | F27: =F11/F18 -> 0.0085285996 | G27: =AVERAGE(C27:F27) -> 0.0080188112 | H27: 0.008 | I27: 0.008 | J27: 0.008 | K27: 0.008
B28: Deferred Membership Fees as a % of Revenue | C28: =C12/C18 -> 0.011470871 | D28: =D12/D18 -> 0.011204757 | E28: =E12/E18 -> 0.011099718 | F28: =F12/F18 -> 0.010422143 | G28: =AVERAGE(C28:F28) -> 0.011049372 | H28: 0.011 | I28: 0.011 | J28: 0.011 | K28: 0.011
B29: Other Current Liabilities as a % of Revenue | C29: =C13/C18 -> 0.020653218 | D29: =D13/D18 -> 0.024832518 | E29: =E13/E18 -> 0.022355347 | F29: =F13/F18 -> 0.023278841 | G29: =AVERAGE(C29:F29) -> 0.022779981 | H29: 0.023 | I29: 0.023 | J29: 0.023 | K29: 0.023

Sheet DCF
B2: Unlevered Free Cash Flow (mm)
B3: Fiscal Year | D3: 43830 | E3: 44196 | F3: 44561 | G3: 44926 | H3: 45291 | I3: 45657 | J3: 46022 | K3: 46387
B4: Unlevered Free Cash Flow | D4: ='Free Cash Flow'!C21 -> 3158 | E4: ='Free Cash Flow'!D21 -> 2859 | F4: ='Free Cash Flow'!E21 -> 4698 | G4: ='Free Cash Flow'!F21 -> 3645.4724 | H4: ='Free Cash Flow'!G21 -> 4100.7944 | I4: ='Free Cash Flow'!H21 -> 4529.3774 | J4: ='Free Cash Flow'!I21 -> 4828.694 | K4: ='Free Cash Flow'!J21 -> 4963.3221
B6: Projection Year | G6: 1 | H6: 2 | I6: 3 | J6: 4 | K6: 5
B7: Present Value of Free Cash Flow | G7: =G4/(1+$C$12)^(G6) -> 3431.5086 | H7: =H4/(1+$C$12)^(H6) -> 3633.5452 | I7: =I4/(1+$C$12)^(I6) -> 3777.7426 | J7: =J4/(1+$C$12)^(J6) -> 3791.009 | K7: =K4/(1+$C$12)^(K6) -> 3667.9963
B9: Implied Share Price Calculation | E9: Sensitivity Table
B10: Sum of PV of FCF | C10: =SUM(G7:K7) -> 18301.802
B11: Growth Rate | C11: 0.03 | G11: Growth Rate
B12: WACC | C12: =WACC!C18 -> 0.062352676 | F12: =C21 -> 242.72775 | G12: 0.02 | H12: 0.025 | I12: =C11 -> 0.03 | J12: =3.5% -> 0.035 | K12: 0.04
B13: Terminal Value | C13: =K7*(1+C11)/(C12-C11) -> 116776.62 | E13: WACC | F13: 0.0524 | G13: 260.71364 | H13: 300.44177 | I13: 300.44177 | J13: 448.39478 | K13: 611.859
B14: PV of Terminal Value | C14: =C13/(1+C12)^K6 -> 86300.303 | F14: 0.0574 | G14: 223.43398 | H14: 251.32413 | I14: 251.32413 | J14: 344.4573 | K14: 431.1675
B15: Enterprise Value | C15: =C14+C10 -> 104602.11 | F15: =C12 -> 0.062352676 | G15: 223.43398 | H15: 251.32413 | I15: 251.32413 | J15: 344.4573 | K15: 431.1675
B16: (+) Cash | C16: ='Balance Sheet'!F4 -> 11258 | F16: 0.0674 | G16: 173.12083 | H16: 188.57096 | I16: 188.57096 | J16: 233.77691 | K16: 268.75377
B17: (-) Debt | C17: =WACC!C4 -> 7491 | F17: 0.0724 | G17: 155.43434 | H17: 167.42105 | I17: 167.42105 | J17: 201.00951 | K17: 225.57884
B18: (-) Minority Interest | C18: ='Balance Sheet'!F35 -> 514
B19: Equity Value | C19: =C15+C16-C17-C18 -> 107855.11
B20: Diluted Shares Outstanding (mm) | C20: 444.346
B21: Implied Share Price | C21: =C19/C20 -> 242.72775
E24: TV = Final-year FCF × (1 + g) / (WACC − g)

Sheet WACC
B2: Weighted Average Cost of Capital (WACC)
B3: Equity (mm) | C3: 214560
B4: Debt (mm) | C4: =SUM('Balance Sheet'!F20,'Balance Sheet'!F24) -> 7491 | E4: E(Ri) = Rf + Bi*(E(Rm)-Rf)
B6: Cost of Debt | C6: =-'Income Statement'!E13/WACC!C4 -> 0.022827393
B7: Tax Rate | C7: 0.21
B8: D/(D+E) | C8: =C4/(C4+C3) -> 0.033735493
B9: After Tax Cost of Debt | C9: =C6*(1-C7) -> 0.01803364
B10: CAPM ASSUMPTIONS
B11: Risk Free Rate (10-Yr Treasury Yield) | C11: 0.031
B12: Expected Market Return | C12: 0.078
B13: Market Risk Premium | C13: =C12-C11 -> 0.047
B14: Levered Beta | C14: 0.7
B15: E/(D+E) | C15: =C3/(C3+C4) -> 0.96626451
B16: Cost of Equity | C16: =C11+(C14*C13) -> 0.0639
F17: WACC = Cost of Equity × E/(D+E) + After-tax Cost of Debt × D/(D+E)
B18: WACC | C18: =C16*C15+C8*C9 -> 0.062352676

Sheet Income Statement
B2: Consolidated Statements Of Income - USD ($) shares in Thousands, $ in Millions
C3: Sep. 01, 2019 | D3: Aug. 30, 2020 | E3: Aug. 29, 2021
B4: REVENUE
B5: Total revenue | C5: 152703 | D5: 166761 | E5: 195929
B6: OPERATING EXPENSES
B7: Merchandise costs | C7: 132886 | D7: 144939 | E7: 170684
B8: Selling, general and administrative | C8: 13502 | D8: 14687 | E8: 16680
B9: Depreciation & Amortization | C9: 1492 | D9: 1645 | E9: 1781
B10: Preopening expenses | C10: 86 | D10: 55 | E10: 76
B11: Operating Income | C11: 4737 | D11: 5435 | E11: 6708
B12: OTHER INCOME (EXPENSE)
B13: Interest expense | C13: -150 | D13: -160 | E13: -171
B14: Interest income and other, net | C14: 178 | D14: 92 | E14: 143
B15: INCOME BEFORE INCOME TAXES | C15: 4765 | D15: 5367 | E15: 6680
B16: Income Tax Expense (Benefit) | C16: 1061 | D16: 1308 | E16: 1601
B17: Net Income | C17: 3704 | D17: 4059 | E17: 5079
B19: Diluted (shares) | C19: 442923 | D19: 443901 | E19: 444346
B21: Merchandise Sales Revenue | C21: 149351 | D21: 163220 | E21: 192052
B22: Membership Fee Revenue | C22: 3352 | D22: 3541 | E22: 3877
D27: =171/7491 -> 0.022827393

Sheet Balance Sheet
B2: Consolidated Balance Sheets - USD ($) $ in Millions | C2: Sep. 02, 2018 | D2: Sep. 01, 2019 | E2: Aug. 30, 2020 | F2: Aug. 29, 2021
B3: CURRENT ASSETS
B4: Cash and cash equivalents | C4: 6055 | D4: 8384 | E4: 12277 | F4: 11258
B5: Short-term investments | C5: 1204 | D5: 1060 | E5: 1028 | F5: 917
B6: Receivables, net | C6: 1669 | D6: 1535 | E6: 1550 | F6: 1803
B7: Merchandise inventories | C7: 11040 | D7: 11395 | E7: 12242 | F7: 14215
B8: Other current assets | C8: 321 | D8: 1111 | E8: 1023 | F8: 1312
B9: Total current assets | C9: 20289 | D9: 23485 | E9: 28120 | F9: 29505
B10: OTHER ASSETS
B11: Property and Equipment, net | C11: 19681 | D11: 20890 | E11: 21807 | F11: 23492
B12: Operating lease right-of-use assets | D12: 0 | E12: 2788 | F12: 2890
B13: Other long-term assets | C13: 860 | D13: 1025 | E13: 2841 | F13: 3381
B14: TOTAL ASSETS | C14: 40830 | D14: 45400 | E14: 55556 | F14: 59268
B15: CURRENT LIABILITIES
B16: Accounts payable | C16: 11237 | D16: 11679 | E16: 14172 | F16: 16278
B17: Accrued salaries and benefits | C17: 2994 | D17: 3176 | E17: 3605 | F17: 4090
B18: Accrued member rewards | C18: 1057 | D18: 1180 | E18: 1393 | F18: 1671
B19: Deferred membership fees | C19: 1624 | D19: 1711 | E19: 1851 | F19: 2042
B20: Current portion of long-term debt | C20: 90 | D20: 1699 | E20: 95 | F20: 799
B21: Other current liabilities | C21: 2924 | D21: 3792 | E21: 3728 | F21: 4561
B22: Total current liabilities | C22: 19926 | D22: 23237 | E22: 24844 | F22: 29441
B23: OTHER LIABILITIES
B24: Long-term debt, excluding current portion | C24: 6487 | D24: 5124 | E24: 7514 | F24: 6692
B25: Long-term operating lease liabilities | D25: 0 | E25: 2558 | F25: 2642
B26: Other long-term liabilities | C26: 1314 | D26: 1455 | E26: 1935 | F26: 2415
B27: Total liabilities | C27: 27727 | D27: 29816 | E27: 36851 | F27: 41190
B28: EQUITY
B29: Preferred stock $.01 par value; 100,000,000 shares authorized; no shares issued and outstanding | C29: 0 | D29: 0 | E29: 0 | F29: 0
B30: Common Stock $.01 par value; 100,000,000 shares authorized; 441,825,000 and 441,255,000 shares issued and outstanding | C30: 4 | D30: 4 | E30: 4 | F30: 4
B31: Additional paid-in capital | C31: 6107 | D31: 6417 | E31: 6698 | F31: 7031
B32: Accumulated other comprehensive loss | C32: -1199 | D32: -1436 | E32: -1297 | F32: -1137
B33: Retained earnings | C33: 7887 | D33: 10258 | E33: 12879 | F33: 11666
B34: Total Costco stockholders' equity | C34: 12799 | D34: 15243 | E34: 18284 | F34: 17564
B35: Noncontrolling interests | C35: 304 | D35: 341 | E35: 421 | F35: 514
B36: Total equity | C36: 13103 | D36: 15584 | E36: 18705 | F36: 18078
B37: TOTAL LIABILITIES AND EQUITY | C37: 40830 | D37: 45400 | E37: 55556 | F37: 59268

Sheet Cash Flow Statement
B2: Consolidated Statements Of Cash Flows - USD ($) $ in Millions
C3: Sep. 01, 2019 | D3: Aug. 30, 2020 | E3: Aug. 29, 2021
B4: CASH FLOWS FROM OPERATING ACTIVITIES
B5: Net income including noncontrolling interests | C5: 3704 | D5: 4059 | E5: 5079
B6: Adjustments to reconcile net income including noncontrolling interests to net cash provided by operating activities:
B7: Depreciation and amortization | C7: 1492 | D7: 1645 | E7: 1781
B8: Non-cash lease expense | C8: 0 | D8: 194 | E8: 286
B9: Stock-based compensation | C9: 595 | D9: 619 | E9: 665
B10: Other non-cash operating activities, net | C10: 9 | D10: 42 | E10: 85
B11: Deferred income taxes | C11: 147 | D11: 104 | E11: 59
B12: Changes in operating assets and liabilities:
B13: Merchandise inventories | C13: -536 | D13: -791 | E13: -1892
B14: Accounts payable | C14: 322 | D14: 2261 | E14: 1838
B15: Other operating assets and liabilities, net | C15: 623 | D15: 728 | E15: 1057
B16: Net Cash Provided by (Used in) Operating Activities | C16: 6356 | D16: 8861 | E16: 8958
B17: CASH FLOWS FROM INVESTING ACTIVITIES
B18: Purchases of short-term investments | C18: -1094 | D18: -1626 | E18: -1331
B19: Maturities and sales of short-term investments | C19: 1231 | D19: 1678 | E19: 1446
B20: Additions to property and equipment | C20: -2998 | D20: -2810 | E20: -3588
B21: Acquisitions | C21: 0 | D21: -1163 | E21: 0
B22: Other investing activities, net | C22: -4 | D22: 30 | E22: -62
B23: Net Cash Provided by (Used in) Investing Activities | C23: -2865 | D23: -3891 | E23: -3535
B24: CASH FLOWS FROM FINANCING ACTIVITIES
B25: Change in bank payments outstanding | C25: 210 | D25: 137 | E25: 188
B26: Proceeds from short-term borrowings | C26: 0 | D26: 0 | E26: 41
B27: Proceeds from issuance of long-term debt | C27: 298 | D27: 3992 | E27: 0
B28: Repayments of long-term debt | C28: -89 | D28: -3200 | E28: -94
B29: Tax withholdings on stock-based awards | C29: -272 | D29: -330 | E29: -312
B30: Repurchases of common stock | C30: -247 | D30: -196 | E30: -496
B31: Cash dividend payments | C31: -1038 | D31: -1479 | E31: -5748
B32: Other financing activities, net | C32: -9 | D32: -71 | E32: -67
B33: Net Cash Provided by (Used in) Financing Activities | C33: -1147 | D33: -1147 | E33: -6488
B34: EFFECT OF EXCHANGE RATE CHANGES ON CASH AND CASH EQUIVALENTS | C34: -15 | D34: 70 | E34: 46
B35: Net change in cash and cash equivalents | C35: 2329 | D35: 3893 | E35: -1019
B36: CASH AND CASH EQUIVALENTS BEGINNING OF YEAR | C36: 6055 | D36: 8384 | E36: 12277
B37: CASH AND CASH EQUIVALENTS END OF YEAR | C37: 8384 | D37: 12277 | E37: 11258
B38: SUPPLEMENTAL DISCLOSURE OF CASH FLOW INFORMATION:
B39: Interest paid | C39: 141 | D39: 124 | E39: 149
B40: Income taxes paid, net | C40: 1187 | D40: 1052 | E40: 1527
B41: SUPPLEMENTAL DISCLOSURE OF NON-CASH INVESTING AND FINANCING ACTIVITIES:
...
